Workbook

Sheet (2026) 08-06 ~ 08-12
B1: 해외사업운영팀 주간보고 | E1: 08-06~08-12 (2026년)
B2: TN | C2: 사이트 | D2: 파트 | E2: 내용 | F2: REQUEST TYPE | G2: 담당자 | H2: 금주 진행상황 | I2: M/H | J2: 예상 공수 | K2: 진행률 | L2: 완료 예정일 | M2: 비고(특이사항, 이슈, 기타)
B3: TN | C3: 사이트 | D3: CMC Dubai | E3: 내용 | F3: REQUEST TYPE | G3: 담당자 | H3: 금주 진행상황 | I3: M/H | J3: 예상공수 | K3: 진행률 | L3: 완료 예정일 | M3: 비고(특이사항, 이슈, 기타)
B4: 진료/간호
C5: CMC-D | D5: 진료/간호
C6: CMC-D | D6: 진료/간호
C7: CMC-D | D7: 진료/간호
C8: CMC-D | D8: 진료/간호
C9: CMC-D | D9: 진료/간호
C10: CMC-D | D10: 진료/간호
C11: CMC-D | D11: 진료/간호
C12: CMC-D | D12: 진료/간호
B13: 진료지원
C14: CMC-D | D14: 진료지원
C15: CMC-D | D15: 진료지원
C16: CMC-D | D16: 진료지원
C17: CMC-D | D17: 진료지원
C18: CMC-D | D18: 진료지원
E19: =IFERROR(VLOOKUP(B19, [1]업무!B:C, 2, FALSE),"")
E20: =IFERROR(VLOOKUP(B20, [1]업무!B:C, 2, FALSE),"")
B21: 원무
C22: CMC-D | D22: 원무
C23: CMC-D | D23: 원무 | E23: =IFERROR(VLOOKUP(B23, [1]업무!B:C, 2, FALSE),"")
E24: =IFERROR(VLOOKUP(B24, [1]업무!B:C, 2, FALSE),"")
B25: TN | C25: 사이트 | D25: RCJY | E25: 내용 | F25: REQUEST TYPE | G25: 담당자 | H25: 금주 진행상황 | I25: M/H | J25: 예상공수 | K25: 진행률 | L25: 완료 예정일 | M25: 비고(특이사항, 이슈, 기타)
B26: 진료/간호
B27: 13024 | C27: RCJY | D27: 진료/간호 | E27: RE: DHS-Bestcare Integration Update Approval API | F27: Program Modification | G27: 박제현 | H27: 완료 | I27: 4 | J27: 4 | K27: 1 | L27: 46246 | M27: 외래/응급 환자의 UCAF/DCAF 서명 시, 기록 내용 BASE64 인코딩 저장 후, DHS API 호출 응급 환자의 응급 초진기록 서명 시, DHS API 호출
B28: 13024 | C28: RCJY | D28: 진료/간호 | E28: RE: DHS-Bestcare Integration Update Approval API | F28: Program Modification | G28: 강진규 | H28: 완료 | M28: 처치지시오더 중 처치료오더 존재하는 경우 처치료 ORD_ID로 DHS 상태값 조회되게 수정
C29: RCJY | D29: 진료/간호
C30: RCJY | D30: 진료/간호
C31: RCJY | D31: 진료/간호
C32: RCJY | D32: 진료/간호
C33: RCJY | D33: 진료/간호 | E33: =IFERROR(VLOOKUP(B33, [1]업무!B:C, 2, FALSE),"")
C34: RCJY | D34: 진료/간호 | E34: =IFERROR(VLOOKUP(B34, [1]업무!B:C, 2, FALSE),"")
E35: =IFERROR(VLOOKUP(B35, [1]업무!B:C, 2, FALSE),"")
E36: =IFERROR(VLOOKUP(B36, [1]업무!B:C, 2, FALSE),"")
B37: 진료지원
C38: RCJY | D38: 진료지원
C39: RCJY | D39: 진료지원
C40: RCJY | D40: 진료지원
...
